<robot name="onshape">
<link name="compact_excavator_cabin_body_cmpl">
<visual>
<origin xyz="0.15929227608280682738 -0.2512819772778476235 0.33139999999999991687" rpy="1.570796326794896558 -9.3057818912215613423e-24 -4.5449756518009500624e-16" />
<geometry>
<mesh filename="package:///compact_excavator_cabin_body.stl"/>
</geometry>
<material name="compact_excavator_cabin_body_material">
<color rgba="0.2313725490196078538 0.38039215686274507888 0.7058823529411765163 1.0"/>
</material>
</visual>
<collision>
<origin xyz="0.15929227608280682738 -0.2512819772778476235 0.33139999999999991687" rpy="1.570796326794896558 -9.3057818912215613423e-24 -4.5449756518009500624e-16" />
<geometry>
<mesh filename="package:///compact_excavator_cabin_body.stl"/>
</geometry>
</collision>
<inertial>
<origin xyz="-0.14687259964422888503 0.44115718470639297966 0.45091673023147632593" rpy="0 0 0"/>
<mass value="9732.8038980797628028" />
<inertia ixx="3175.1655302028066217" ixy="-269.97312494382805426"  ixz="167.61780128589862215" iyy="2627.6328649732404301" iyz="-193.85494965010821034" izz="3742.6160472748279062" />
</inertial>
</link>

<link name="part01_pin_1">
<visual>
<origin xyz="2.7755575615628913511e-17 0.074999999999999955591 -0.14999999999999996669" rpy="-1.570796326794896336 -6.1629758220391547298e-33 -3.9110122218931175387e-17" />
<geometry>
<mesh filename="package:///part01_pin_1.stl"/>
</geometry>
<material name="part01_pin_1_material">
<color rgba="0.61568627450980395466 0.81176470588235294379 0.92941176470588238168 1.0"/>
</material>
</visual>
<collision>
<origin xyz="2.7755575615628913511e-17 0.074999999999999955591 -0.14999999999999996669" rpy="-1.570796326794896336 -6.1629758220391547298e-33 -3.9110122218931175387e-17" />
<geometry>
<mesh filename="package:///part01_pin_1.stl"/>
</geometry>
</collision>
<inertial>
<origin xyz="-0.026030309007671007665 0.10672288733099301317 0.097553850513847420456" rpy="0 0 0"/>
<mass value="98.140190062279046401" />
<inertia ixx="2.6085778666185075458" ixy="0.04022730090195379693"  ixz="0.4213678311955360023" iyy="3.1665232143977135593" iyz="-0.15916376835413631463" izz="1.7889951810686837153" />
</inertial>
</link>

<link name="part02_cmpl">
<visual>
<origin xyz="-5.5511151231257827021e-17 -1.1102230246251565404e-16 -0.079999999999999960032" rpy="1.788366166767622739e-17 3.1515725624365876964e-17 8.3986930507683979021e-18" />
<geometry>
<mesh filename="package:///part02.stl"/>
</geometry>
<material name="part02_material">
<color rgba="0.77647058823529413463 0.7568627450980391913 0.73725490196078435901 1.0"/>
</material>
</visual>
<collision>
<origin xyz="-5.5511151231257827021e-17 -1.1102230246251565404e-16 -0.079999999999999960032" rpy="1.788366166767622739e-17 3.1515725624365876964e-17 8.3986930507683979021e-18" />
<geometry>
<mesh filename="package:///part02.stl"/>
</geometry>
</collision>
<inertial>
<origin xyz="-0.04007940207094681101 1.215334476695421273 -0.079873417172118821306" rpy="0 0 0"/>
<mass value="694.1779351385806649" />
<inertia ixx="242.81245205849668878" ixy="71.370938403077801127"  ixz="0.0065905643878621592013" iyy="49.641340591529463211" iyz="-0.034260052091466569602" izz="289.83702909122933988" />
</inertial>
</link>

<link name="part03">
<visual>
<origin xyz="0 0 -0.055000000000000076605" rpy="-3.141592653589793116 1.0340875198291035432e-17 2.2621709890826693666e-18" />
<geometry>
<mesh filename="package:///part03.stl"/>
</geometry>
<material name="part03_material">
<color rgba="0.98039215686274505668 0.71372549019607844922 0.0039215686274509803377 1.0"/>
</material>
</visual>
<collision>
<origin xyz="0 0 -0.055000000000000076605" rpy="-3.141592653589793116 1.0340875198291035432e-17 2.2621709890826693666e-18" />
<geometry>
<mesh filename="package:///part03.stl"/>
</geometry>
</collision>
<inertial>
<origin xyz="0.10866226733951291072 -0.6016479735090608516 -0.055167291851018936122" rpy="0 0 0"/>
<mass value="265.34907807560875881" />
<inertia ixx="57.599134249663777041" ixy="0.07844258055421660103"  ixz="0.0049826290162331291281" iyy="1.8968981412117766894" iyz="0.024599016056534125929" izz="58.868680211308245021" />
</inertial>
</link>

<link name="part04">
<visual>
<origin xyz="0.059999999999999942268 0.14000000000000012434 0.054999999999999882316" rpy="-1.570796326794896558 -1.570796326794896558 0" />
<geometry>
<mesh filename="package:///part04.stl"/>
</geometry>
<material name="part04_material">
<color rgba="0.76862745098039220171 0.88627450980392152857 0.95294117647058818044 1.0"/>
</material>
</visual>
<collision>
<origin xyz="0.059999999999999942268 0.14000000000000012434 0.054999999999999882316" rpy="-1.570796326794896558 -1.570796326794896558 0" />
<geometry>
<mesh filename="package:///part04.stl"/>
</geometry>
</collision>
<visual>
<origin xyz="0.078718096856642633119 0.97961106773941608594 0.054999999999995080602" rpy="9.65360195140036553e-15 3.0312973336399180687e-15 3.0159289474462180891" />
<geometry>
<mesh filename="package:///bucket.stl"/>
</geometry>
<material name="bucket_material">
<color rgba="0.61568627450980395466 0.81176470588235294379 0.92941176470588238168 1.0"/>
</material>
</visual>
<collision>
<origin xyz="0.078718096856642633119 0.97961106773941608594 0.054999999999995080602" rpy="9.65360195140036553e-15 3.0312973336399180687e-15 3.0159289474462180891" />
<geometry>
<mesh filename="package:///bucket.stl"/>
</geometry>
</collision>
<visual>
<origin xyz="0.1699999999999974587 0.30800000000000204992 0.054999999999999243938" rpy="-3.1415926535897793492 -1.570796326794896558 0" />
<geometry>
<mesh filename="package:///bucket_mount.stl"/>
</geometry>
<material name="bucket_mount_material">
<color rgba="0.49803921568627451677 0.49803921568627451677 0.49803921568627451677 1.0"/>
</material>
</visual>
<collision>
<origin xyz="0.1699999999999974587 0.30800000000000204992 0.054999999999999243938" rpy="-3.1415926535897793492 -1.570796326794896558 0" />
<geometry>
<mesh filename="package:///bucket_mount.stl"/>
</geometry>
</collision>
<inertial>
<origin xyz="0.21363777998580446571 0.42618058483692822236 0.0550714974547636682" rpy="0 0 0"/>
<mass value="132.70765933863822283" />
<inertia ixx="14.035671877901600979" ixy="-1.6652440163769273163"  ixz="0.0020270508814540203098" iyy="6.8549730106957875719" iyz="0.0040437120644074217579" izz="11.610921270718637999" />
</inertial>
</link>

<joint name="scoop1" type="revolute">
<origin xyz="0.1200000000000036593 -1.540332756257559943 9.4368957093138305936e-16" rpy="3.1415926535897917837 7.373202369705688962e-16 -1.4390399398611677384" />
<parent link="part03" />
<child link="part04" />
<axis xyz="0 0 1"/>
<limit effort="1" velocity="20" lower="-1.2217304763960306069" upper="0.87266462599716476678"/>
<joint_properties friction="0.0"/>
</joint>

<joint name="upperToLow" type="revolute">
<origin xyz="-0.83999999999999930278 2.3549999999999999822 -0.13500000000000023093" rpy="3.1415926535897922278 5.5237799528035288331e-15 2.4777537169378613946" />
<parent link="part02_cmpl" />
<child link="part03" />
<axis xyz="0 0 1"/>
<limit effort="1" velocity="20" />
<joint_properties friction="0.0"/>
</joint>

<joint name="lower_arm" type="revolute">
<origin xyz="0.080000000000000265343 0.074999999999998845368 -0.15000000000000018874" rpy="-1.57079632679489678 0.62798416085350616811 -1.5707963267948996666" />
<parent link="part01_pin_1" />
<child link="part02_cmpl" />
<axis xyz="0 0 1"/>
<limit effort="1" velocity="20" />
<joint_properties friction="0.0"/>
</joint>

<joint name="full_arm_rotation" type="revolute">
<origin xyz="-0.040707723917193447405 -0.80673603465099630316 0.38039999999999996039" rpy="3.141592653589793116 4.8797124238540929311e-17 0.21446312817660284633" />
<parent link="compact_excavator_cabin_body_cmpl" />
<child link="part01_pin_1" />
<axis xyz="0 0 1"/>
<limit effort="1" velocity="20" />
<joint_properties friction="0.0"/>
</joint>

<link name="compact_excavator_turret_cabin_roller">
<visual>
<origin xyz="-0.25 -2.6186110041323504109e-15 0" rpy="-1.570796326794896558 -0 -1.2325977355371927047e-32" />
<geometry>
<mesh filename="package:///compact_excavator_turret_cabin_roller.stl"/>
</geometry>
<material name="compact_excavator_turret_cabin_roller_material">
<color rgba="0.98039215686274505668 0.71372549019607844922 0.0039215686274509803377 1.0"/>
</material>
</visual>
<collision>
<origin xyz="-0.25 -2.6186110041323504109e-15 0" rpy="-1.570796326794896558 -0 -1.2325977355371927047e-32" />
<geometry>
<mesh filename="package:///compact_excavator_turret_cabin_roller.stl"/>
</geometry>
</collision>
<inertial>
<origin xyz="-0.25 -2.6054840351250470264e-15 -0.024479606502805662666" rpy="0 0 0"/>
<mass value="72.827596459303620691" />
<inertia ixx="1.099653317522871987" ixy="-2.7108603781094622134e-32"  ixz="-1.2447660391936817316e-72" iyy="1.0996533175228726531" iyz="2.999005425890207397e-40" izz="2.1659744096152295789" />
</inertial>
</link>

<link name="compact_excavator_frame_body">
<visual>
<origin xyz="0.57449999999997003464 0.79999999999999993339 -0.27500000000000024425" rpy="1.5998727561897592153 9.6017146690291203134e-17 -3.141592653589793116" />
<geometry>
<mesh filename="package:///compact_excavator_front_wheel.stl"/>
</geometry>
<material name="compact_excavator_front_wheel_material">
<color rgba="0.91764705882352937127 0.91764705882352937127 0.91764705882352937127 1.0"/>
</material>
</visual>
<collision>
<origin xyz="0.57449999999997003464 0.79999999999999993339 -0.27500000000000024425" rpy="1.5998727561897592153 9.6017146690291203134e-17 -3.141592653589793116" />
<geometry>
<mesh filename="package:///compact_excavator_front_wheel.stl"/>
</geometry>
</collision>
<visual>
<origin xyz="-0.5805000000000005711 0.80000000000000015543 -0.27499999999999991118" rpy="0.94609869190098605518 1.4900399985966125054e-16 -1.0485591267771783955e-16" />
<geometry>
<mesh filename="package:///compact_excavator_front_wheel.stl"/>
</geometry>
<material name="compact_excavator_front_wheel_material">
<color rgba="0.91764705882352937127 0.91764705882352937127 0.91764705882352937127 1.0"/>
</material>
</visual>
<collision>
<origin xyz="-0.5805000000000005711 0.80000000000000015543 -0.27499999999999991118" rpy="0.94609869190098605518 1.4900399985966125054e-16 -1.0485591267771783955e-16" />
<geometry>
<mesh filename="package:///compact_excavator_front_wheel.stl"/>
</geometry>
</collision>
<visual>
<origin xyz="-3.0814879110195773649e-33 8.7258015952359846036e-17 -0.11999999999999998168" rpy="1.570796326794896558 -0 -1.1127370557393788133e-19" />
<geometry>
<mesh filename="package:///compact_excavator_frame_body.stl"/>
</geometry>
<material name="compact_excavator_frame_body_material">
<color rgba="0.91764705882352937127 0.91764705882352937127 0.91764705882352937127 1.0"/>
</material>
</visual>
<collision>
<origin xyz="-3.0814879110195773649e-33 8.7258015952359846036e-17 -0.11999999999999998168" rpy="1.570796326794896558 -0 -1.1127370557393788133e-19" />
<geometry>
<mesh filename="package:///compact_excavator_frame_body.stl"/>
</geometry>
</collision>
<visual>
<origin xyz="0.58399999999999119282 0.0003381516737085757114 -0.25174213399088585241" rpy="1.5417198974000221323 9.9938523491654756324e-17 1.2194918171911379701e-15" />
<geometry>
<mesh filename="package:///track_chain.stl"/>
</geometry>
<material name="track_chain_material">
<color rgba="0.76862745098039220171 0.88627450980392152857 0.95294117647058818044 1.0"/>
</material>
</visual>
<collision>
<origin xyz="0.58399999999999119282 0.0003381516737085757114 -0.25174213399088585241" rpy="1.5417198974000221323 9.9938523491654756324e-17 1.2194918171911379701e-15" />
<geometry>
<mesh filename="package:///track_chain.stl"/>
</geometry>
</collision>
<visual>
<origin xyz="-0.58899999999999930189 -0.024536590298994853665 -0.26946556212505834438" rpy="1.5695183747476746383 8.7997350825076917345e-19 -1.4661131769766482343e-17" />
<geometry>
<mesh filename="package:///track_chain.stl"/>
</geometry>
<material name="track_chain_material">
<color rgba="0.76862745098039220171 0.88627450980392152857 0.95294117647058818044 1.0"/>
</material>
</visual>
<collision>
<origin xyz="-0.58899999999999930189 -0.024536590298994853665 -0.26946556212505834438" rpy="1.5695183747476746383 8.7997350825076917345e-19 -1.4661131769766482343e-17" />
<geometry>
<mesh filename="package:///track_chain.stl"/>
</geometry>
</collision>
<visual>
<origin xyz="0.58899999999999974598 -0.80000000000000004441 -0.27499999999999991118" rpy="1.570796326794896558 1.3666512641579369181 1.5707963267948941155" />
<geometry>
<mesh filename="package:///compact_excavator_main_drive_wheel.stl"/>
</geometry>
<material name="compact_excavator_main_drive_wheel_material">
<color rgba="0.91764705882352937127 0.91764705882352937127 0.91764705882352937127 1.0"/>
</material>
</visual>
<collision>
<origin xyz="0.58899999999999974598 -0.80000000000000004441 -0.27499999999999991118" rpy="1.570796326794896558 1.3666512641579369181 1.5707963267948941155" />
<geometry>
<mesh filename="package:///compact_excavator_main_drive_wheel.stl"/>
</geometry>
</collision>
<visual>
<origin xyz="-0.588999999999999857 -0.80000000000000015543 -0.2750000000000000222" rpy="1.570796326794896558 0.63576722493071868847 -1.5707963267948985564" />
<geometry>
<mesh filename="package:///compact_excavator_main_drive_wheel.stl"/>
</geometry>
<material name="compact_excavator_main_drive_wheel_material">
<color rgba="0.91764705882352937127 0.91764705882352937127 0.91764705882352937127 1.0"/>
</material>
</visual>
<collision>
<origin xyz="-0.588999999999999857 -0.80000000000000015543 -0.2750000000000000222" rpy="1.570796326794896558 0.63576722493071868847 -1.5707963267948985564" />
<geometry>
<mesh filename="package:///compact_excavator_main_drive_wheel.stl"/>
</geometry>
</collision>
<inertial>
<origin xyz="-0.0038186118657760341651 -0.071070009907850062447 -0.23294001240469949798" rpy="0 0 0"/>
<mass value="1357.3931058603629936" />
<inertia ixx="517.60924982120457116" ixy="-2.9035153993129707573"  ixz="-4.2797378194687683006" iyy="418.35984621444436016" iyz="-3.2731464486072385789" izz="866.57358808866308664" />
</inertial>
</link>

<link name="push_blade_bucket">
<visual>
<origin xyz="-0.021564399534920564161 1.0799900599760596798 -0.25500000000000000444" rpy="-1.570796326794896558 -1.570796326794896558 0" />
<geometry>
<mesh filename="package:///push_blade_bucket.stl"/>
</geometry>
<material name="push_blade_bucket_material">
<color rgba="0.61568627450980395466 0.81176470588235294379 0.92941176470588238168 1.0"/>
</material>
</visual>
<collision>
<origin xyz="-0.021564399534920564161 1.0799900599760596798 -0.25500000000000000444" rpy="-1.570796326794896558 -1.570796326794896558 0" />
<geometry>
<mesh filename="package:///push_blade_bucket.stl"/>
</geometry>
</collision>
<inertial>
<origin xyz="-0.10970493109347193017 0.88075063461342895099 -0.25500033703320834633" rpy="0 0 0"/>
<mass value="147.01808168083411488" />
<inertia ixx="31.881096131626389223" ixy="0.91247385061899766168"  ixz="-1.6212090668107553485e-05" iyy="21.196220352263189568" iyz="4.9900082201963374081e-06" izz="13.169227707961482565" />
</inertial>
</link>

<joint name="plow1" type="revolute">
<origin xyz="-0.25500000000000000444 0.48799999999999998934 -0.20500000000000001554" rpy="1.570796326794896558 -1.3195606112546156563 -1.5707963267948994446" />
<parent link="compact_excavator_frame_body" />
<child link="push_blade_bucket" />
<axis xyz="0 0 1"/>
<limit effort="1" velocity="20" />
<joint_properties friction="0.0"/>
</joint>

<joint name="tankBase_wheel" type="continuous">
<origin xyz="-0.25 -2.5715909255520656419e-15 -0.049999999999999961142" rpy="1.1763052875827275422e-17 1.9830083989986516138e-17 3.1020655818367162126" />
<parent link="compact_excavator_turret_cabin_roller" />
<child link="compact_excavator_frame_body" />
<axis xyz="0 0 1"/>
<limit effort="1" velocity="20" />
<joint_properties friction="0.0"/>
</joint>

<joint name="fixedbase" type="fixed">
<origin xyz="-0.25 -2.394831672112794725e-15 0.049999999999999988898" rpy="-6.5400986663891116335e-25 -1.0029564927205460558e-23 3.1415926535897926719" />
<parent link="compact_excavator_cabin_body_cmpl" />
<child link="compact_excavator_turret_cabin_roller" />
<axis xyz="0 0 1"/>
<limit effort="1" velocity="20" />
<joint_properties friction="0.0"/>
</joint>


</robot>
